恭喜！

Solidity 中的自定义错误由其 4 字节签名标识，与函数调用相同。 它们在调用链中被向上抛出，直到被 try-catch 块中的 catch 语句捕获，如 GoodSamaritan 的 `requestDonation()` 函数所示。 由于这些原因，假设错误是由合约调用的直接目标（即本例中的钱包）引发的是不安全的。

调用链中更靠后的任何其他合约都可以声明相同的错误——具有相同的签名——将其抛出到意想不到的位置，例如在攻击者合约中的 `notify(uint256 amount)` 函数中。